<?xml version="1.0" encoding="utf-8"?>
<!-- This URDF was automatically created by SolidWorks to URDF Exporter! Originally created by Stephen Brawner (brawner@gmail.com) 
     Commit Version: 1.6.0-4-g7f85cfe  Build Version: 1.6.7995.38578
     For more information, please see http://wiki.ros.org/sw_urdf_exporter -->
<robot
  name="tank_rocket">
  <link
    name="khung">
    <inertial>
      <origin
        xyz="0.0563929386010087 1.31019476305321E-05 -0.041762838953123"
        rpy="0 0 0" />
      <mass
        value="4.63698631254725" />
      <inertia
        ixx="0.00845788314060549"
        ixy="-4.14679616592237E-10"
        ixz="0.00097950998612986"
        iyy="0.0175516900060017"
        iyz="1.90560315093228E-10"
        izz="0.0230333628752782" />
    </inertial>
    <visual>
      <origin
        xyz="0 0 0"
        rpy="0 0 0" />
      <geometry>
        <mesh
          filename="package://tank_rocket/meshes/khung.STL" />
      </geometry>
      <material
        name="">
        <color
          rgba="0.776470588235294 0.756862745098039 0.737254901960784 1" />
      </material>
    </visual>
    <collision>
      <origin
        xyz="0 0 0"
        rpy="0 0 0" />
      <geometry>
        <mesh
          filename="package://tank_rocket/meshes/khung.STL" />
      </geometry>
    </collision>
  </link>
  <link
    name="right_front">
    <inertial>
      <origin
        xyz="2.45775622076394E-14 -2.56877852322646E-14 0.0150066275369927"
        rpy="0 0 0" />
      <mass
        value="0.16560407234294" />
      <inertia
        ixx="2.27667842545529E-05"
        ixy="-1.13844085310617E-20"
        ixz="-2.09528282705332E-21"
        iyy="2.27667842545529E-05"
        iyz="7.62220485665021E-21"
        izz="2.44403723155893E-05" />
    </inertial>
    <visual>
      <origin
        xyz="0 0 0"
        rpy="0 0 0" />
      <geometry>
        <mesh
          filename="package://tank_rocket/meshes/right_front.STL" />
      </geometry>
      <material
        name="">
        <color
          rgba="0.650980392156863 0.619607843137255 0.588235294117647 1" />
      </material>
    </visual>
    <collision>
      <origin
        xyz="0 0 0"
        rpy="0 0 0" />
      <geometry>
        <mesh
          filename="package://tank_rocket/meshes/right_front.STL" />
      </geometry>
    </collision>
  </link>
  <joint
    name="joint_right_front"
    type="continuous">
    <origin
      xyz="0.127499999999975 -0.095 -0.0875000000000256"
      rpy="-1.5707963267949 0 0" />
    <parent
      link="khung" />
    <child
      link="right_front" />
    <axis
      xyz="0 0 1" />
    <dynamics
      damping="0.1"
      friction="0.1" />
  </joint>
  <link
    name="right_back">
    <inertial>
      <origin
        xyz="5.77315972805081E-15 6.09928774153445E-15 0.0150066275369927"
        rpy="0 0 0" />
      <mass
        value="0.165604072342939" />
      <inertia
        ixx="2.27667842545528E-05"
        ixy="-8.72298939981801E-22"
        ixz="2.94735102771319E-21"
        iyy="2.27667842545528E-05"
        iyz="-8.60682594730567E-21"
        izz="2.44403723155892E-05" />
    </inertial>
    <visual>
      <origin
        xyz="0 0 0"
        rpy="0 0 0" />
      <geometry>
        <mesh
          filename="package://tank_rocket/meshes/right_back.STL" />
      </geometry>
      <material
        name="">
        <color
          rgba="0.650980392156863 0.619607843137255 0.588235294117647 1" />
      </material>
    </visual>
    <collision>
      <origin
        xyz="0 0 0"
        rpy="0 0 0" />
      <geometry>
        <mesh
          filename="package://tank_rocket/meshes/right_back.STL" />
      </geometry>
    </collision>
  </link>
  <joint
    name="joint_right_back"
    type="continuous">
    <origin
      xyz="0.00249999999999424 -0.095 -0.087499999999994"
      rpy="-1.5707963267949 0 0" />
    <parent
      link="khung" />
    <child
      link="right_back" />
    <axis
      xyz="0 0 1" />
    <dynamics
      damping="0.1"
      friction="0.1" />
  </joint>
  <link
    name="left_front">
    <inertial>
      <origin
        xyz="-3.06976666308856E-14 3.2009117578724E-14 -0.0150066275369927"
        rpy="0 0 0" />
      <mass
        value="0.165604072342939" />
      <inertia
        ixx="2.27667842545528E-05"
        ixy="3.7787980095971E-21"
        ixz="9.74684171212316E-22"
        iyy="2.27667842545528E-05"
        iyz="-8.87836025018574E-21"
        izz="2.44403723155892E-05" />
    </inertial>
    <visual>
      <origin
        xyz="0 0 0"
        rpy="0 0 0" />
      <geometry>
        <mesh
          filename="package://tank_rocket/meshes/left_front.STL" />
      </geometry>
      <material
        name="">
        <color
          rgba="0.650980392156863 0.619607843137255 0.588235294117647 1" />
      </material>
    </visual>
    <collision>
      <origin
        xyz="0 0 0"
        rpy="0 0 0" />
      <geometry>
        <mesh
          filename="package://tank_rocket/meshes/left_front.STL" />
      </geometry>
    </collision>
  </link>
  <joint
    name="joint_left_front"
    type="continuous">
    <origin
      xyz="0.127499999999969 0.095 -0.087500000000032"
      rpy="1.5707963267949 0 3.14159265358979" />
    <parent
      link="khung" />
    <child
      link="left_front" />
    <axis
      xyz="0 0 1" />
    <limit
      lower="0"
      upper="0"
      effort="0"
      velocity="0" />
    <dynamics
      damping="0.1"
      friction="0.1" />
  </joint>
  <link
    name="left_back">
    <inertial>
      <origin
        xyz="-4.20913304211012E-14 -4.39370761995406E-14 -0.0150066275369927"
        rpy="0 0 0" />
      <mass
        value="0.16560407234294" />
      <inertia
        ixx="2.27667842545529E-05"
        ixy="3.95310284523938E-21"
        ixz="8.76303048343584E-21"
        iyy="2.27667842545529E-05"
        iyz="-6.35784847258839E-21"
        izz="2.44403723155893E-05" />
    </inertial>
    <visual>
      <origin
        xyz="0 0 0"
        rpy="0 0 0" />
      <geometry>
        <mesh
          filename="package://tank_rocket/meshes/left_back.STL" />
      </geometry>
      <material
        name="">
        <color
          rgba="0.650980392156863 0.619607843137255 0.588235294117647 1" />
      </material>
    </visual>
    <collision>
      <origin
        xyz="0 0 0"
        rpy="0 0 0" />
      <geometry>
        <mesh
          filename="package://tank_rocket/meshes/left_back.STL" />
      </geometry>
    </collision>
  </link>
  <joint
    name="joint_left_back"
    type="continuous">
    <origin
      xyz="0.0025 0.095 -0.0875"
      rpy="1.5708 0 3.1416" />
    <parent
      link="khung" />
    <child
      link="left_back" />
    <axis
      xyz="0 0 1" />
    <limit
      lower="0"
      upper="0"
      effort="0"
      velocity="0" />
    <dynamics
      damping="0.1"
      friction="0.1" />
  </joint>
  <link
    name="link_1">
    <inertial>
      <origin
        xyz="1.38777878078145E-17 1.21430643318376E-17 0.00644835915793762"
        rpy="0 0 0" />
      <mass
        value="0.0346715546726792" />
      <inertia
        ixx="7.54524817502026E-06"
        ixy="1.5425914273849E-06"
        ixz="5.95382956038774E-22"
        iyy="4.20922960466919E-06"
        iyz="-1.73405803358085E-21"
        izz="9.78608502282708E-06" />
    </inertial>
    <visual>
      <origin
        xyz="0 0 0"
        rpy="0 0 0" />
      <geometry>
        <mesh
          filename="package://tank_rocket/meshes/link_1.STL" />
      </geometry>
      <material
        name="">
        <color
          rgba="0.2 0.2 0.2 1" />
      </material>
    </visual>
    <collision>
      <origin
        xyz="0 0 0"
        rpy="0 0 0" />
      <geometry>
        <mesh
          filename="package://tank_rocket/meshes/link_1.STL" />
      </geometry>
    </collision>
  </link>
  <joint
    name="joint_link_1"
    type="revolute">
    <origin
      xyz="0 0 0"
      rpy="0 0 0.0667722831295613" />
    <parent
      link="khung" />
    <child
      link="link_1" />
    <axis
      xyz="0 0 1" />
    <limit
      lower="0"
      upper="0"
      effort="0"
      velocity="0" />
    <dynamics
      damping="0.1"
      friction="0.1" />
  </joint>
  <link
    name="link_2">
    <inertial>
      <origin
        xyz="-0.0127749750502287 0.0648357593087863 0.0060136139065154"
        rpy="0 0 0" />
      <mass
        value="0.703700638958416" />
      <inertia
        ixx="0.000439347414549989"
        ixy="-0.000148738322351986"
        ixz="6.1377914180307E-05"
        iyy="0.00042013773576176"
        iyz="7.00140276744204E-05"
        izz="0.000540847242016088" />
    </inertial>
    <visual>
      <origin
        xyz="0 0 0"
        rpy="0 0 0" />
      <geometry>
        <mesh
          filename="package://tank_rocket/meshes/link_2.STL" />
      </geometry>
      <material
        name="">
        <color
          rgba="0.650980392156863 0.619607843137255 0.588235294117647 1" />
      </material>
    </visual>
    <collision>
      <origin
        xyz="0 0 0"
        rpy="0 0 0" />
      <geometry>
        <mesh
          filename="package://tank_rocket/meshes/link_2.STL" />
      </geometry>
    </collision>
  </link>
  <joint
    name="joint_link_2"
    type="revolute">
    <origin
      xyz="0 0 0.01"
      rpy="1.5707963267949 0 -0.0667722831295613" />
    <parent
      link="link_1" />
    <child
      link="link_2" />
    <axis
      xyz="-0.0667226763982024 0 -0.997771559253049" />
    <limit
      lower="0"
      upper="0"
      effort="0"
      velocity="0" />
    <dynamics
      damping="0.1"
      friction="0.1" />
  </joint>
  <link
    name="lidar">
    <inertial>
      <origin
        xyz="-0.0117920609089138 0.000367882733003611 -0.0355014080779145"
        rpy="0 0 0" />
      <mass
        value="0.0941040902130198" />
      <inertia
        ixx="2.79091491936744E-05"
        ixy="-5.25179299565225E-08"
        ixz="3.35339141518402E-07"
        iyy="4.43526924858989E-05"
        iyz="-2.48697913621617E-08"
        izz="6.9475343834523E-05" />
    </inertial>
    <visual>
      <origin
        xyz="0 0 0"
        rpy="0 0 0" />
      <geometry>
        <mesh
          filename="package://tank_rocket/meshes/lidar.STL" />
      </geometry>
      <material
        name="">
        <color
          rgba="0.752941176470588 0.752941176470588 0.752941176470588 1" />
      </material>
    </visual>
    <collision>
      <origin
        xyz="0 0 0"
        rpy="0 0 0" />
      <geometry>
        <mesh
          filename="package://tank_rocket/meshes/lidar.STL" />
      </geometry>
    </collision>
  </link>
  <joint
    name="joint_lidar"
    type="fixed">
    <origin
      xyz="0.13485 -0.0025353 0.037632"
      rpy="0 0 0" />
    <parent
      link="khung" />
    <child
      link="lidar" />
    <axis
      xyz="0 0 0" />
    <dynamics
      damping="0.1"
      friction="0.1" />
  </joint>
  <link
    name="camera">
    <inertial>
      <origin
        xyz="-2.53358309080798E-05 -0.00506843406603578 3.54461215884784E-11"
        rpy="0 0 0" />
      <mass
        value="0.000771122618586836" />
      <inertia
        ixx="1.1165460947251E-08"
        ixy="5.62819447235883E-11"
        ixz="-1.05364985326774E-16"
        iyy="9.6034226519931E-09"
        iyz="-7.04412393831707E-17"
        izz="1.11009840028505E-08" />
    </inertial>
    <visual>
      <origin
        xyz="0 0 0"
        rpy="0 0 0" />
      <geometry>
        <mesh
          filename="package://tank_rocket/meshes/camera.STL" />
      </geometry>
      <material
        name="">
        <color
          rgba="1 1 1 1" />
      </material>
    </visual>
    <collision>
      <origin
        xyz="0 0 0"
        rpy="0 0 0" />
      <geometry>
        <mesh
          filename="package://tank_rocket/meshes/camera.STL" />
      </geometry>
    </collision>
  </link>
  <joint
    name="joint_camera"
    type="fixed">
    <origin
      xyz="0.16324 0 0.047632"
      rpy="1.5708 0 0" />
    <parent
      link="khung" />
    <child
      link="camera" />
    <axis
      xyz="0 0 0" />
    <dynamics
      damping="0.1"
      friction="0.1" />
  </joint>
  <link
    name="gps">
    <inertial>
      <origin
        xyz="1.38777878078145E-17 1.04709948019378E-19 -0.00503945929130452"
        rpy="0 0 0" />
      <mass
        value="0.000778957433419712" />
      <inertia
        ixx="1.12317823812769E-08"
        ixy="1.14794486789053E-41"
        ixz="-2.85942737532526E-41"
        iyy="1.12317823812769E-08"
        iyz="1.15470852006784E-25"
        izz="9.66985366827311E-09" />
    </inertial>
    <visual>
      <origin
        xyz="0 0 0"
        rpy="0 0 0" />
      <geometry>
        <mesh
          filename="package://tank_rocket/meshes/gps.STL" />
      </geometry>
      <material
        name="">
        <color
          rgba="0.101960784313725 0.101960784313725 0.101960784313725 1" />
      </material>
    </visual>
    <collision>
      <origin
        xyz="0 0 0"
        rpy="0 0 0" />
      <geometry>
        <mesh
          filename="package://tank_rocket/meshes/gps.STL" />
      </geometry>
    </collision>
  </link>
  <joint
    name="joint_gps"
    type="fixed">
    <origin
      xyz="0.18126 0 -0.015"
      rpy="0 0 0" />
    <parent
      link="khung" />
    <child
      link="gps" />
    <axis
      xyz="0 0 0" />
    <dynamics
      damping="0.1"
      friction="0.1" />
  </joint>
</robot>